2020-06-04 22:33:35,502 INFO: Bots control startup [in C:/Users/colak/Desktop/Cola Bot/bot_control/start.py:349]
2020-06-04 22:39:11,014 INFO: Bots control startup [in C:/Users/colak/Desktop/Cola Bot/bot_control/start.py:349]
2020-06-04 22:39:15,681 ERROR: Exception on / [GET] [in C:\Python37\lib\site-packages\flask\app.py:1892]
Traceback (most recent call last):
  File "C:\Python37\lib\site-packages\flask\app.py", line 2447, in wsgi_app
    response = self.full_dispatch_request()
  File "C:\Python37\lib\site-packages\flask\app.py", line 1952, in full_dispatch_request
    rv = self.handle_user_exception(e)
  File "C:\Python37\lib\site-packages\flask\app.py", line 1821, in handle_user_exception
    reraise(exc_type, exc_value, tb)
  File "C:\Python37\lib\site-packages\flask\_compat.py", line 39, in reraise
    raise value
  File "C:\Python37\lib\site-packages\flask\app.py", line 1950, in full_dispatch_request
    rv = self.dispatch_request()
  File "C:\Python37\lib\site-packages\flask\app.py", line 1936, in dispatch_request
    return self.view_functions[rule.endpoint](**req.view_args)
  File "C:\Users\colak\Desktop\Cola Bot\bot_control\app\routes.py", line 33, in home_page
    return redirect(url_for('bots_page'))
  File "C:\Python37\lib\site-packages\flask\helpers.py", line 370, in url_for
    return appctx.app.handle_url_build_error(error, endpoint, values)
  File "C:\Python37\lib\site-packages\flask\app.py", line 2216, in handle_url_build_error
    reraise(exc_type, exc_value, tb)
  File "C:\Python37\lib\site-packages\flask\_compat.py", line 39, in reraise
    raise value
  File "C:\Python37\lib\site-packages\flask\helpers.py", line 358, in url_for
    endpoint, values, method=method, force_external=external
  File "C:\Python37\lib\site-packages\werkzeug\routing.py", line 2179, in build
    raise BuildError(endpoint, values, method, self)
werkzeug.routing.BuildError: Could not build url for endpoint 'bots_page'. Did you mean 'home_page' instead?
2020-06-04 22:39:16,800 ERROR: Exception on / [GET] [in C:\Python37\lib\site-packages\flask\app.py:1892]
Traceback (most recent call last):
  File "C:\Python37\lib\site-packages\flask\app.py", line 2447, in wsgi_app
    response = self.full_dispatch_request()
  File "C:\Python37\lib\site-packages\flask\app.py", line 1952, in full_dispatch_request
    rv = self.handle_user_exception(e)
  File "C:\Python37\lib\site-packages\flask\app.py", line 1821, in handle_user_exception
    reraise(exc_type, exc_value, tb)
  File "C:\Python37\lib\site-packages\flask\_compat.py", line 39, in reraise
    raise value
  File "C:\Python37\lib\site-packages\flask\app.py", line 1950, in full_dispatch_request
    rv = self.dispatch_request()
  File "C:\Python37\lib\site-packages\flask\app.py", line 1936, in dispatch_request
    return self.view_functions[rule.endpoint](**req.view_args)
  File "C:\Users\colak\Desktop\Cola Bot\bot_control\app\routes.py", line 33, in home_page
    return redirect(url_for('bots_page'))
  File "C:\Python37\lib\site-packages\flask\helpers.py", line 370, in url_for
    return appctx.app.handle_url_build_error(error, endpoint, values)
  File "C:\Python37\lib\site-packages\flask\app.py", line 2216, in handle_url_build_error
    reraise(exc_type, exc_value, tb)
  File "C:\Python37\lib\site-packages\flask\_compat.py", line 39, in reraise
    raise value
  File "C:\Python37\lib\site-packages\flask\helpers.py", line 358, in url_for
    endpoint, values, method=method, force_external=external
  File "C:\Python37\lib\site-packages\werkzeug\routing.py", line 2179, in build
    raise BuildError(endpoint, values, method, self)
werkzeug.routing.BuildError: Could not build url for endpoint 'bots_page'. Did you mean 'home_page' instead?
2020-06-04 22:52:10,515 INFO: Bots control startup [in C:/Users/colak/Desktop/Cola Bot/bot_control/start.py:349]
2020-06-04 22:52:11,854 ERROR: Exception on / [GET] [in C:\Python37\lib\site-packages\flask\app.py:1892]
Traceback (most recent call last):
  File "C:\Python37\lib\site-packages\flask\app.py", line 2447, in wsgi_app
    response = self.full_dispatch_request()
  File "C:\Python37\lib\site-packages\flask\app.py", line 1952, in full_dispatch_request
    rv = self.handle_user_exception(e)
  File "C:\Python37\lib\site-packages\flask\app.py", line 1821, in handle_user_exception
    reraise(exc_type, exc_value, tb)
  File "C:\Python37\lib\site-packages\flask\_compat.py", line 39, in reraise
    raise value
  File "C:\Python37\lib\site-packages\flask\app.py", line 1950, in full_dispatch_request
    rv = self.dispatch_request()
  File "C:\Python37\lib\site-packages\flask\app.py", line 1936, in dispatch_request
    return self.view_functions[rule.endpoint](**req.view_args)
  File "C:\Users\colak\Desktop\Cola Bot\bot_control\app\routes.py", line 33, in home_page
    return redirect(url_for('bots_page'))
  File "C:\Python37\lib\site-packages\flask\helpers.py", line 370, in url_for
    return appctx.app.handle_url_build_error(error, endpoint, values)
  File "C:\Python37\lib\site-packages\flask\app.py", line 2216, in handle_url_build_error
    reraise(exc_type, exc_value, tb)
  File "C:\Python37\lib\site-packages\flask\_compat.py", line 39, in reraise
    raise value
  File "C:\Python37\lib\site-packages\flask\helpers.py", line 358, in url_for
    endpoint, values, method=method, force_external=external
  File "C:\Python37\lib\site-packages\werkzeug\routing.py", line 2179, in build
    raise BuildError(endpoint, values, method, self)
werkzeug.routing.BuildError: Could not build url for endpoint 'bots_page'. Did you mean 'home_page' instead?
2020-06-04 22:53:59,813 INFO: Bots control startup [in C:/Users/colak/Desktop/Cola Bot/bot_control/start.py:349]
2020-06-04 22:54:00,638 ERROR: Exception on / [GET] [in C:\Python37\lib\site-packages\flask\app.py:1892]
Traceback (most recent call last):
  File "C:\Python37\lib\site-packages\flask\app.py", line 2447, in wsgi_app
    response = self.full_dispatch_request()
  File "C:\Python37\lib\site-packages\flask\app.py", line 1952, in full_dispatch_request
    rv = self.handle_user_exception(e)
  File "C:\Python37\lib\site-packages\flask\app.py", line 1821, in handle_user_exception
    reraise(exc_type, exc_value, tb)
  File "C:\Python37\lib\site-packages\flask\_compat.py", line 39, in reraise
    raise value
  File "C:\Python37\lib\site-packages\flask\app.py", line 1950, in full_dispatch_request
    rv = self.dispatch_request()
  File "C:\Python37\lib\site-packages\flask\app.py", line 1936, in dispatch_request
    return self.view_functions[rule.endpoint](**req.view_args)
  File "C:\Users\colak\Desktop\Cola Bot\bot_control\app\routes.py", line 33, in home_page
    return redirect(url_for('bots_page'))
  File "C:\Python37\lib\site-packages\flask\helpers.py", line 370, in url_for
    return appctx.app.handle_url_build_error(error, endpoint, values)
  File "C:\Python37\lib\site-packages\flask\app.py", line 2216, in handle_url_build_error
    reraise(exc_type, exc_value, tb)
  File "C:\Python37\lib\site-packages\flask\_compat.py", line 39, in reraise
    raise value
  File "C:\Python37\lib\site-packages\flask\helpers.py", line 358, in url_for
    endpoint, values, method=method, force_external=external
  File "C:\Python37\lib\site-packages\werkzeug\routing.py", line 2179, in build
    raise BuildError(endpoint, values, method, self)
werkzeug.routing.BuildError: Could not build url for endpoint 'bots_page'. Did you mean 'home_page' instead?
